Workbook

Sheet raw_data(dont change)
A1: Order ID | B1: Order Date | C1: Customer ID | D1: Type | E1: SKU | F1: Category | G1: Product Name | H1: Unit Price | I1: Qty | J1: Total | K1: Discount Code | L1: Disc % | M1: Payment | N1: Source | O1: City | P1: State | Q1: Warehouse | R1: Del Date | S1: Status | T1: Return? | U1: Reason | V1: Ret Rec | W1: Refund
A2: UT-100001 | B2: 2024-10-01 | C2: CUST_10001 | D2: New | E2: TOP-CAS-M | F2: Tops | G2: Classic Cotton Tee | H2: 1299 | I2: 2 | J2: 2598 | L2: 0 | M2: UPI | N2: Website | O2: Mumbai | P2: Maharashtra | Q2: Mumbai | R2: 2024-10-05 | S2: Delivered | T2: No | W2: Not Applicable
A3: UT-100002 | B3: 2024-10-01 | C3: CUST_10002 | D3: Returning | E3: DRS-FRM-S | F3: Dresses | G3: Floral Midi Dress | H3: 2499 | I3: 1 | J3: 2499 | K3: DIWALI20 | L3: 20 | M3: Credit Card | N3: Mobile App | O3: Delhi | P3: Delhi | Q3: Delhi | R3: 2024-10-04 | S3: Delivered | T3: Yes | U3: Size Issue | V3: 2024-10-15 | W3: Processed
A4: UT-100003 | B4: 2024-01-10 | C4: CUST_10003 | D4: new | E4: BOT-JNS-L | F4: Bottoms | G4: Slim Fit Jeans | H4: 1899 | I4: 1 | J4: 1899 | L4: 0 | M4: COD | N4: Website | O4: Bangalore | P4: Karnataka | Q4: Bangalore | R4: 2024-10-06 | S4: Delivered | T4: No | W4: Not Applicable
A5: UT-100004 | B5: 2024-10-01 | C5: CUST_10004 | D5: New | E5: OUT-JKT-XL | F5: Outerwear | G5: Denim Jacket | H5: 3499 | I5: 1 | J5: 3499 | K5: FIRST15 | L5: 15 | M5: Debit Card | N5: Instagram Shop | O5: Chennai | P5: Tamil Nadu | Q5: Mumbai | R5: 2024-10-08 | S5: Delivered | T5: Yes | U5: Quality Defect | V5: 2024-10-20 | W5: Processed
A6: UT-100005 | B6: 2024-10-01 | C6: CUST_10001 | D6: New | E6: ACC-SCF-OS | F6: Accessories | G6: Silk Scarf | H6: 799 | I6: 3 | J6: 2397 | L6: 0 | M6: UPI | N6: Website | O6: Mumbai | P6: Maharashtra | Q6: Mumbai | R6: 2024-10-06 | S6: Delivered | T6: No | W6: Not Applicable
A7: UT-100006 | B7: 2024-10-02 | C7: CUST_10005 | D7: Returning | E7: TOP-FRM-S | F7: Tops | G7: Printed Blouse | H7: 1599 | I7: 2 | J7: 3198 | L7: 0 | M7: Credit Card | N7: Mobile App | O7: Hyderabad | P7: Telangana | Q7: Bangalore | R7: 2024-10-07 | S7: Delivered | T7: Yes | U7: Changed Mind | V7: 2024-10-18 | W7: Processed
A8: UT-100007 | B8: 2024-10-02 | C8: CUST_10006 | D8: New | E8: DRS-CAS-M | F8: Dresses | G8: A-Line Dress | H8: 2199 | I8: 1 | J8: 2199 | K8: DIWALI20 | L8: 20 | M8: COD | N8: Website | O8: Pune | P8: Maharashtra | Q8: Mumbai | S8: Cancelled | T8: No | W8: Not Applicable
A9: UT-100008 | B9: 2024-10-02 | C9: CUST_10007 | D9: New | E9: BOT-TRS-L | F9: Bottoms | G9: Formal Trousers | H9: 2299 | I9: 1 | J9: 2299 | L9: 0 | M9: UPI | N9: Mobile App | O9: Kolkata | P9: West Bengal | Q9: Delhi | R9: 2024-10-10 | S9: Delivered | T9: No | W9: Not Applicable
A10: UT-100009 | B10: 2024-10-02 | C10: CUST_10008 | D10: Returning | E10: TOP-CAS-XL | F10: Tops | G10: Oversized Tee | H10: 1399 | I10: 5 | J10: 6995 | L10: 0 | M10: Credit Card | N10: Website | O10: Ahmedabad | P10: Gujarat | Q10: Mumbai | R10: 2024-10-09 | S10: Delivered | T10: Yes | U10: Size Issue | V10: 2024-10-22 | W10: Processed
A11: UT-100010 | B11: 2024-10-02 | C11: CUST_10009 | D11: New | E11: OUT-BLZ-M | F11: Outerwear | G11: Casual Blazer | H11: 4999 | I11: -1 | J11: 4999 | L11: 0 | M11: Debit Card | N11: Instagram Shop | O11: Jaipur | P11: Rajasthan | Q11: Delhi | R11: 2024-10-11 | S11: Delivered | T11: Yes | U11: Wrong Item | V11: 2024-10-25 | W11: Pending
A12: UT-100011 | B12: 2024-10-03 | C12: CUST_10010 | D12: New | E12: ACC-BAG-OS | F12: Accessories | G12: Tote Bag | H12: 1299 | I12: 2 | J12: 2598 | K12: FLAT10 | L12: 10 | M12: Wallet | N12: Website | O12: Lucknow | P12: Uttar Pradesh | Q12: Delhi | R12: 2024-10-10 | S12: Delivered | T12: No | W12: Not Applicable
A13: UT-100012 | B13: 2024-10-03 | C13: CUST_10011 | D13: New | E13: DRS-PRT-S | F13: Dresses | G13: Party Dress | H13: 3299 | I13: 1 | J13: 3299 | L13: 0 | M13: COD | N13: Mobile App | O13: Chandigarh | P13: Punjab | Q13: Delhi | S13: RTO | T13: No | W13: Not Applicable
A14: UT-100013 | B14: 2024-10-03 | C14: CUST_10012 | D14: Returning | E14: TOP-SLK-M | F14: Tops | G14: Silk Blouse | H14: 2499 | I14: 1 | J14: 2499 | L14: 0 | M14: Credit Card | N14: Website | O14: Mumbai | P14: Maharashtra | Q14: Mumbai | R14: 2024-10-09 | S14: Delivered | T14: No | W14: Not Applicable
A15: UT-100014 | B15: 2024-10-03 | C15: CUST_10013 | D15: New | E15: BOT-SKT-S | F15: Bottoms | G15: Pleated Skirt | H15: 1799 | I15: 2 | J15: 3598 | K15: DIWALI20 | L15: 20 | M15: UPI | N15: Instagram Shop | O15: Delhi | P15: Delhi | Q15: Delhi | R15: 2024-10-11 | S15: Delivered | T15: Yes | U15: Size Issue | V15: 2024-10-28 | W15: Processed
A16: UT-100015 | B16: 2024-10-03 | C16: CUST_10014 | D16: New | E16: OUT-CRD-L | F16: Outerwear | G16: Knit Cardigan | H16: 2799 | I16: 1 | J16: 2799 | L16: 0 | M16: Debit Card | N16: Mobile App | O16: Bangalore | P16: Karnataka | Q16: Bangalore | R16: 2024-10-12 | S16: Delivered | T16: No | W16: Not Applicable
A17: UT-100016 | B17: 2024-10-04 | C17: CUST_10015 | D17: Returning | E17: ACC-JWL-OS | F17: Accessories | G17: Statement Earrings | H17: 599 | I17: 4 | J17: 2396 | L17: 0 | M17: COD | N17: Website | O17: Noida | P17: Uttar Pradesh | Q17: Delhi | R17: 2024-10-14 | S17: Delivered | T17: Yes | U17: Damaged in Transit | V17: 2024-10-26 | W17: Processed
A18: UT-100017 | B18: 2024-10-04 | C18: CUST_10016 | D18: New | E18: TOP-CRP-XS | F18: Tops | G18: Crop Top | H18: 999 | I18: 1 | J18: 999 | K18: FIRST15 | L18: 15 | M18: UPI | N18: Mobile App | O18: Gurgaon | P18: Haryana | Q18: Delhi | R18: 2024-10-12 | S18: Delievered | T18: No | W18: Not Applicable
A19: UT-100018 | B19: 2024-10-04 | C19: CUST_10017 | D19: New | E19: DRS-MAX-M | F19: Dresses | G19: Maxi Dress | H19: 2899 | I19: 1 | J19: 2899 | L19: 0 | M19: Credit Card | N19: Website | O19: Indore | P19: Madhya Pradesh | Q19: Mumbai | R19: 2024-10-14 | S19: Delivered | T19: No | W19: Not Applicable
A20: UT-100019 | B20: 2024-10-04 | C20: CUST_10018 | D20: Returning | E20: BOT-JGR-M | F20: Bottoms | G20: Joggers | H20: 1499 | I20: 2 | J20: 2998 | L20: 0 | M20: Wallet | N20: Instagram Shop | O20: Surat | P20: Gujarat | Q20: Mumbai | R20: 2024-10-13 | S20: Delivered | T20: Yes | U20: Size Issue | V20: 2024-10-30 | W20: Processed
A21: UT-100020 | B21: 2024-10-05 | C21: CUST_10019 | D21: New | E21: OUT-VST-S | F21: Outerwear | G21: Puffer Vest | H21: 3999 | I21: 1 | J21: 3999 | K21: DIWALI20 | L21: 20 | M21: COD | N21: Website | O21: Patna | P21: Bihar | Q21: Delhi | S21: RTO | T21: No | W21: Not Applicable
A22: UT-100021 | B22: 2024-10-05 | C22: CUST_10020 | D22: New | E22: TOP-TUN-L | F22: Tops | G22: Tunic Top | H22: 1699 | I22: 1 | J22: 1699 | L22: 0 | M22: UPI | N22: Mobile App | O22: Bhopal | P22: Madhya Pradesh | Q22: Mumbai | R22: 2024-10-15 | S22: Delivered | T22: No | W22: Not Applicable
A23: UT-100022 | B23: 2024-10-05 | C23: CUST_10021 | D23: Returning | E23: DRS-SHT-XS | F23: Dresses | G23: Shirt Dress | H23: 2399 | I23: 1 | J23: 2399 | L23: 0 | M23: Credit Card | N23: Website | O23: Nagpur | P23: Maharashtra | Q23: Mumbai | R23: 2024-10-16 | S23: Delivered | T23: Yes | U23: Quality Defect | V23: 2024-11-02 | W23: Processed
A24: UT-100023 | B24: 2024-10-05 | C24: CUST_10022 | D24: New | E24: ACC-BLT-M | F24: Accessories | G24: Leather Belt | H24: 899 | I24: 1 | J24: 899 | K24: FLAT10 | L24: 10 | M24: Debit Card | N24: Mobile App | O24: Coimbatore | P24: Tamil Nadu | Q24: Bangalore | R24: 2024-10-17 | S24: Delivered | T24: No | W24: Not Applicable
A25: UT-100024 | B25: 2024-10-06 | C25: CUST_10023 | D25: New | E25: BOT-SHT-M | F25: Bottoms | G25: Cotton Shorts | H25: 1199 | I25: 3 | J25: 3597 | L25: 0 | M25: COD | N25: Instagram Shop | O25: Kochi | P25: Kerala | Q25: Bangalore | R25: 2024-10-18 | S25: Delivered | T25: Yes | U25: Changed Mind | V25: 2024-11-05 | W25: Processed
A26: UT-100025 | B26: 2024-10-06 | C26: CUST_10024 | D26: New | E26: TOP-PLO-L | F26: Tops | G26: Polo Shirt | H26: 1799 | I26: 2 | J26: 3598 | L26: 0 | M26: UPI | N26: Website | O26: Vizag | P26: Andhra Pradesh | Q26: Bangalore | R26: 2024-10-17 | S26: Delivered | T26: No | W26: Not Applicable
A27: UT-100026 | B27: 2024-10-06 | C27: CUST_10025 | D27: New | E27: DRS-WRK-M | F27: Dresses | G27: Work Dress | H27: 2699 | I27: 1 | J27: 2699 | L27: 0 | M27: Credit Card | N27: Mobile App | O27: Thiruvananthapuram | P27: Kerala | Q27: Bangalore | R27: 2024-10-18 | S27: Delivered | T27: No | W27: Not Applicable
A28: UT-100027 | B28: 2024-10-06 | C28: CUST_10026 | D28: Returning | E28: OUT-TRN-L | F28: Outerwear | G28: Trench Coat | H28: 4599 | I28: 1 | J28: 4599 | K28: FLAT10 | L28: 10 | M28: Debit Card | N28: Website | O28: Mysore | P28: Karnataka | Q28: Bangalore | R28: 2024-10-19 | S28: Delivered | T28: Yes | U28: Size Issue | V28: 2024-11-08 | W28: Processed
A29: UT-100028 | B29: 2024-10-07 | C29: CUST_10027 | D29: New | E29: ACC-HAT-OS | F29: Accessories | G29: Fedora Hat | H29: 1099 | I29: 1 | J29: 1099 | L29: 0 | M29: UPI | N29: Instagram Shop | O29: Vadodara | P29: Gujarat | Q29: Mumbai | R29: 2024-10-20 | S29: Delivered | T29: No | W29: Not Applicable
A30: UT-100029 | B30: 2024-10-07 | C30: CUST_10028 | D30: New | E30: TOP-DNM-M | F30: Tops | G30: Denim Shirt | H30: 1899 | I30: 1 | J30: 1899 | L30: 0 | M30: COD | N30: Mobile App | O30: Rajkot | P30: Gujarat | Q30: Mumbai | S30: RTO | T30: No | W30: Not Applicable
A31: UT-100030 | B31: 2024-10-07 | C31: CUST_10029 | D31: New | E31: BOT-CRG-L | F31: Bottoms | G31: Cargo Pants | H31: 2199 | I31: 1 | J31: 2199 | K31: DIWALI20 | L31: 20 | M31: Credit Card | N31: Website | O31: Kanpur | P31: Uttar Pradesh | Q31: Delhi | R31: 2024-10-20 | S31: Delivered | T31: No | W31: Not Applicable
A32: UT-100031 | B32: 2024-10-07 | C32: CUST_10030 | D32: Returning | E32: DRS-EVE-S | F32: Dresses | G32: Evening Gown | H32: 5499 | I32: 1 | J32: 5499 | L32: 0 | M32: Credit Card | N32: Mobile App | O32: Mumbai | P32: Maharashtra | Q32: Mumbai | R32: 2024-10-21 | S32: Delivered | T32: Yes | U32: Size Issue | V32: 2024-11-10 | W32: Processed
A33: UT-100032 | B33: 2024-10-08 | C33: CUST_10031 | D33: New | E33: TOP-BAS-M | F33: Tops | G33: Basic Tank | H33: 899 | I33: 2 | J33: 1798 | L33: 0 | M33: UPI | N33: Website | O33: Delhi | P33: Delhi | Q33: Delhi | R33: 2024-10-14 | S33: Delivered | T33: No | W33: Not Applicable
A34: UT-100033 | B34: 2024-10-08 | C34: CUST_10032 | D34: New | E34: OUT-WOL-L | F34: Outerwear | G34: Wool Coat | H34: 6999 | I34: 1 | J34: 6999 | K34: FIRST15 | L34: 15 | M34: Debit Card | N34: Instagram Shop | O34: Kolkata | P34: West Bengal | Q34: Delhi | R34: 2024-10-16 | S34: Delivered | T34: Yes | U34: Quality Defect | V34: 2024-11-05 | W34: Processed
A35: UT-100034 | B35: 2024-10-08 | C35: CUST_10033 | D35: Returning | E35: ACC-WCH-OS | F35: Accessories | G35: Fashion Watch | H35: 2999 | I35: 1 | J35: 2999 | L35: 0 | M35: Credit Card | N35: Mobile App | O35: Chennai | P35: Tamil Nadu | Q35: Bangalore | R35: 2024-10-15 | S35: Delivered | T35: No | W35: Not Applicable
A36: UT-100035 | B36: 2024-10-08 | C36: CUST_10034 | D36: New | E36: BOT-DNM-S | F36: Bottoms | G36: Denim Shorts | H36: 1599 | I36: 1 | J36: 1599 | L36: 0 | M36: COD | N36: Website | O36: Hyderabad | P36: Telangana | Q36: Bangalore | R36: 2024-10-17 | S36: Delivered | T36: Yes | U36: Size Issue | V36: 2024-11-08 | W36: Processed
A37: UT-100036 | B37: 2024-10-09 | C37: CUST_10035 | D37: New | E37: DRS-SUN-M | F37: Dresses | G37: Sundress | H37: 1999 | I37: 1 | J37: 1999 | K37: DIWALI20 | L37: 20 | M37: Wallet | N37: Mobile App | O37: Pune | P37: Maharashtra | Q37: Mumbai | R37: 2024-10-16 | S37: Delivered | T37: No | W37: Not Applicable
A38: UT-100037 | B38: 2024-10-09 | C38: CUST_10036 | D38: New | E38: TOP-RFL-S | F38: Tops | G38: Ruffle Top | H38: 1799 | I38: 1 | J38: 1799 | L38: 0 | M38: UPI | N38: Instagram Shop | O38: Ahmedabad | P38: Gujarat | Q38: Mumbai | R38: 2024-10-17 | S38: Delivered | T38: Yes | U38: Changed Mind | V38: 2024-11-12 | W38: Processed
A39: UT-100038 | B39: 2024-10-09 | C39: CUST_10037 | D39: Returning | E39: OUT-LTH-M | F39: Outerwear | G39: Leather Jacket | H39: 7999 | I39: 1 | J39: 7999 | L39: 0 | M39: Credit Card | N39: Website | O39: Jaipur | P39: Rajasthan | Q39: Delhi | R39: 2024-10-18 | S39: Delivered | T39: No | W39: Not Applicable
A40: UT-100039 | B40: 2024-10-09 | C40: CUST_10038 | D40: New | E40: ACC-SNG-OS | F40: Accessories | G40: Sunglasses | H40: 1499 | I40: 1 | J40: 1499 | K40: FLAT10 | L40: 10 | M40: Debit Card | N40: Mobile App | O40: Lucknow | P40: Uttar Pradesh | Q40: Delhi | R40: 2024-10-17 | S40: Delivered | T40: No | W40: Not Applicable
...

Sheet Working_Data
A1: Order ID | B1: Order Date | C1: Customer ID | D1: Type | E1: SKU | F1: Category | G1: Product Name | H1: Unit Price | I1: Qty | J1: Total | K1: Discount Code | L1: Disc % | M1: Payment | N1: Source | O1: City | P1: State | Q1: Warehouse | R1: Del Date | S1: Status | T1: Return? | U1: Reason | V1: Ret Rec | W1: Refund | Y1: Week_Start | Z1: Delivery Days | AA1: Discount Trap
A2: UT-100001 | B2: 2024-10-01 | C2: CUST_10001 | D2: New | E2: TOP-CAS-M | F2: Tops | G2: Classic Cotton Tee | H2: 1299 | I2: 2 | J2: 2598 | L2: 0 | M2: UPI | N2: Website | O2: Mumbai | P2: Maharashtra | Q2: Mumbai | R2: 2024-10-05 | S2: Delivered | T2: No | W2: Not Applicable | Y2: =B2 - WEEKDAY(B2,2) + 1 -> 2024-09-30 | Z2: =IF(R2<>"", R2-B2, "") -> 4 | AA2: =IF(L2=0, "No Discount", IF(L2<=20, "Low (1-20%)", "High (20%+)")) -> No Discount
A3: UT-100002 | B3: 2024-10-01 | C3: CUST_10002 | D3: Returning | E3: DRS-FRM-S | F3: Dresses | G3: Floral Midi Dress | H3: 2499 | I3: 1 | J3: 2499 | K3: DIWALI20 | L3: 20 | M3: Credit Card | N3: Mobile App | O3: Delhi | P3: Delhi | Q3: Delhi | R3: 2024-10-04 | S3: Delivered | T3: Yes | U3: Size Issue | V3: 2024-10-15 | W3: Processed | Y3: =B3 - WEEKDAY(B3,2) + 1 -> 2024-09-30 | Z3: =IF(R3<>"", R3-B3, "") -> 3 | AA3: =IF(L3=0, "No Discount", IF(L3<=20, "Low (1-20%)", "High (20%+)")) -> Low (1-20%)
A4: UT-100003 | B4: 2024-10-01 | C4: CUST_10003 | D4: new | E4: BOT-JNS-L | F4: Bottoms | G4: Slim Fit Jeans | H4: 1899 | I4: 1 | J4: 1899 | L4: 0 | M4: COD | N4: Website | O4: Bangalore | P4: Karnataka | Q4: Bangalore | R4: 2024-10-06 | S4: Delivered | T4: No | W4: Not Applicable | Y4: =B4 - WEEKDAY(B4,2) + 1 -> 2024-09-30 | Z4: =IF(R4<>"", R4-B4, "") -> 5 | AA4: =IF(L4=0, "No Discount", IF(L4<=20, "Low (1-20%)", "High (20%+)")) -> No Discount
A5: UT-100004 | B5: 2024-10-01 | C5: CUST_10004 | D5: New | E5: OUT-JKT-XL | F5: Outerwear | G5: Denim Jacket | H5: 3499 | I5: 1 | J5: 3499 | K5: FIRST15 | L5: 15 | M5: Debit Card | N5: Instagram Shop | O5: Chennai | P5: Tamil Nadu | Q5: Mumbai | R5: 2024-10-08 | S5: Delivered | T5: Yes | U5: Quality Defect | V5: 2024-10-20 | W5: Processed | Y5: =B5 - WEEKDAY(B5,2) + 1 -> 2024-09-30 | Z5: =IF(R5<>"", R5-B5, "") -> 7 | AA5: =IF(L5=0, "No Discount", IF(L5<=20, "Low (1-20%)", "High (20%+)")) -> Low (1-20%)
A6: UT-100005 | B6: 2024-10-01 | C6: CUST_10001 | D6: New | E6: ACC-SCF-OS | F6: Accessories | G6: Silk Scarf | H6: 799 | I6: 3 | J6: 2397 | L6: 0 | M6: UPI | N6: Website | O6: Mumbai | P6: Maharashtra | Q6: Mumbai | R6: 2024-10-06 | S6: Delivered | T6: No | W6: Not Applicable | Y6: =B6 - WEEKDAY(B6,2) + 1 -> 2024-09-30 | Z6: =IF(R6<>"", R6-B6, "") -> 5 | AA6: =IF(L6=0, "No Discount", IF(L6<=20, "Low (1-20%)", "High (20%+)")) -> No Discount
A7: UT-100006 | B7: 2024-10-02 | C7: CUST_10005 | D7: Returning | E7: TOP-FRM-S | F7: Tops | G7: Printed Blouse | H7: 1599 | I7: 2 | J7: 3198 | L7: 0 | M7: Credit Card | N7: Mobile App | O7: Hyderabad | P7: Telangana | Q7: Bangalore | R7: 2024-10-07 | S7: Delivered | T7: Yes | U7: Changed Mind | V7: 2024-10-18 | W7: Processed | Y7: =B7 - WEEKDAY(B7,2) + 1 -> 2024-09-30 | Z7: =IF(R7<>"", R7-B7, "") -> 5 | AA7: =IF(L7=0, "No Discount", IF(L7<=20, "Low (1-20%)", "High (20%+)")) -> No Discount
A8: UT-100007 | B8: 2024-10-02 | C8: CUST_10006 | D8: New | E8: DRS-CAS-M | F8: Dresses | G8: A-Line Dress | H8: 2199 | I8: 1 | J8: 2199 | K8: DIWALI20 | L8: 20 | M8: COD | N8: Website | O8: Pune | P8: Maharashtra | Q8: Mumbai | S8: Cancelled | T8: No | W8: Not Applicable | Y8: =B8 - WEEKDAY(B8,2) + 1 -> 2024-09-30 | Z8: =IF(R8<>"", R8-B8, "") | AA8: =IF(L8=0, "No Discount", IF(L8<=20, "Low (1-20%)", "High (20%+)")) -> Low (1-20%)
A9: UT-100008 | B9: 2024-10-02 | C9: CUST_10007 | D9: New | E9: BOT-TRS-L | F9: Bottoms | G9: Formal Trousers | H9: 2299 | I9: 1 | J9: 2299 | L9: 0 | M9: UPI | N9: Mobile App | O9: Kolkata | P9: West Bengal | Q9: Delhi | R9: 2024-10-10 | S9: Delivered | T9: No | W9: Not Applicable | Y9: =B9 - WEEKDAY(B9,2) + 1 -> 2024-09-30 | Z9: =IF(R9<>"", R9-B9, "") -> 8 | AA9: =IF(L9=0, "No Discount", IF(L9<=20, "Low (1-20%)", "High (20%+)")) -> No Discount
A10: UT-100009 | B10: 2024-10-02 | C10: CUST_10008 | D10: Returning | E10: TOP-CAS-XL | F10: Tops | G10: Oversized Tee | H10: 1399 | I10: 5 | J10: 6995 | L10: 0 | M10: Credit Card | N10: Website | O10: Ahmedabad | P10: Gujarat | Q10: Mumbai | R10: 2024-10-09 | S10: Delivered | T10: Yes | U10: Size Issue | V10: 2024-10-22 | W10: Processed | Y10: =B10 - WEEKDAY(B10,2) + 1 -> 2024-09-30 | Z10: =IF(R10<>"", R10-B10, "") -> 7 | AA10: =IF(L10=0, "No Discount", IF(L10<=20, "Low (1-20%)", "High (20%+)")) -> No Discount
A11: UT-100010 | B11: 2024-10-02 | C11: CUST_10009 | D11: New | E11: OUT-BLZ-M | F11: Outerwear | G11: Casual Blazer | H11: 4999 | I11: -1 | J11: 4999 | L11: 0 | M11: Debit Card | N11: Instagram Shop | O11: Jaipur | P11: Rajasthan | Q11: Delhi | R11: 2024-10-11 | S11: Delivered | T11: Yes | U11: Wrong Item | V11: 2024-10-25 | W11: Pending | Y11: =B11 - WEEKDAY(B11,2) + 1 -> 2024-09-30 | Z11: =IF(R11<>"", R11-B11, "") -> 9 | AA11: =IF(L11=0, "No Discount", IF(L11<=20, "Low (1-20%)", "High (20%+)")) -> No Discount
A12: UT-100011 | B12: 2024-10-03 | C12: CUST_10010 | D12: New | E12: ACC-BAG-OS | F12: Accessories | G12: Tote Bag | H12: 1299 | I12: 2 | J12: 2598 | K12: FLAT10 | L12: 10 | M12: Wallet | N12: Website | O12: Lucknow | P12: Uttar Pradesh | Q12: Delhi | R12: 2024-10-10 | S12: Delivered | T12: No | W12: Not Applicable | Y12: =B12 - WEEKDAY(B12,2) + 1 -> 2024-09-30 | Z12: =IF(R12<>"", R12-B12, "") -> 7 | AA12: =IF(L12=0, "No Discount", IF(L12<=20, "Low (1-20%)", "High (20%+)")) -> Low (1-20%)
A13: UT-100012 | B13: 2024-10-03 | C13: CUST_10011 | D13: New | E13: DRS-PRT-S | F13: Dresses | G13: Party Dress | H13: 3299 | I13: 1 | J13: 3299 | L13: 0 | M13: COD | N13: Mobile App | O13: Chandigarh | P13: Punjab | Q13: Delhi | S13: RTO | T13: No | W13: Not Applicable | Y13: =B13 - WEEKDAY(B13,2) + 1 -> 2024-09-30 | Z13: =IF(R13<>"", R13-B13, "") | AA13: =IF(L13=0, "No Discount", IF(L13<=20, "Low (1-20%)", "High (20%+)")) -> No Discount
A14: UT-100013 | B14: 2024-10-03 | C14: CUST_10012 | D14: Returning | E14: TOP-SLK-M | F14: Tops | G14: Silk Blouse | H14: 2499 | I14: 1 | J14: 2499 | L14: 0 | M14: Credit Card | N14: Website | O14: Mumbai | P14: Maharashtra | Q14: Mumbai | R14: 2024-10-09 | S14: Delivered | T14: No | W14: Not Applicable | Y14: =B14 - WEEKDAY(B14,2) + 1 -> 2024-09-30 | Z14: =IF(R14<>"", R14-B14, "") -> 6 | AA14: =IF(L14=0, "No Discount", IF(L14<=20, "Low (1-20%)", "High (20%+)")) -> No Discount
A15: UT-100014 | B15: 2024-10-03 | C15: CUST_10013 | D15: New | E15: BOT-SKT-S | F15: Bottoms | G15: Pleated Skirt | H15: 1799 | I15: 2 | J15: 3598 | K15: DIWALI20 | L15: 20 | M15: UPI | N15: Instagram Shop | O15: Delhi | P15: Delhi | Q15: Delhi | R15: 2024-10-11 | S15: Delivered | T15: Yes | U15: Size Issue | V15: 2024-10-28 | W15: Processed | Y15: =B15 - WEEKDAY(B15,2) + 1 -> 2024-09-30 | Z15: =IF(R15<>"", R15-B15, "") -> 8 | AA15: =IF(L15=0, "No Discount", IF(L15<=20, "Low (1-20%)", "High (20%+)")) -> Low (1-20%)
A16: UT-100015 | B16: 2024-10-03 | C16: CUST_10014 | D16: New | E16: OUT-CRD-L | F16: Outerwear | G16: Knit Cardigan | H16: 2799 | I16: 1 | J16: 2799 | L16: 0 | M16: Debit Card | N16: Mobile App | O16: Bangalore | P16: Karnataka | Q16: Bangalore | R16: 2024-10-12 | S16: Delivered | T16: No | W16: Not Applicable | Y16: =B16 - WEEKDAY(B16,2) + 1 -> 2024-09-30 | Z16: =IF(R16<>"", R16-B16, "") -> 9 | AA16: =IF(L16=0, "No Discount", IF(L16<=20, "Low (1-20%)", "High (20%+)")) -> No Discount
A17: UT-100016 | B17: 2024-10-04 | C17: CUST_10015 | D17: Returning | E17: ACC-JWL-OS | F17: Accessories | G17: Statement Earrings | H17: 599 | I17: 4 | J17: 2396 | L17: 0 | M17: COD | N17: Website | O17: Noida | P17: Uttar Pradesh | Q17: Delhi | R17: 2024-10-14 | S17: Delivered | T17: Yes | U17: Damaged in Transit | V17: 2024-10-26 | W17: Processed | Y17: =B17 - WEEKDAY(B17,2) + 1 -> 2024-09-30 | Z17: =IF(R17<>"", R17-B17, "") -> 10 | AA17: =IF(L17=0, "No Discount", IF(L17<=20, "Low (1-20%)", "High (20%+)")) -> No Discount
A18: UT-100017 | B18: 2024-10-04 | C18: CUST_10016 | D18: New | E18: TOP-CRP-XS | F18: Tops | G18: Crop Top | H18: 999 | I18: 1 | J18: 999 | K18: FIRST15 | L18: 15 | M18: UPI | N18: Mobile App | O18: Gurgaon | P18: Haryana | Q18: Delhi | R18: 2024-10-12 | S18: Delivered | T18: No | W18: Not Applicable | Y18: =B18 - WEEKDAY(B18,2) + 1 -> 2024-09-30 | Z18: =IF(R18<>"", R18-B18, "") -> 8 | AA18: =IF(L18=0, "No Discount", IF(L18<=20, "Low (1-20%)", "High (20%+)")) -> Low (1-20%)
A19: UT-100018 | B19: 2024-10-04 | C19: CUST_10017 | D19: New | E19: DRS-MAX-M | F19: Dresses | G19: Maxi Dress | H19: 2899 | I19: 1 | J19: 2899 | L19: 0 | M19: Credit Card | N19: Website | O19: Indore | P19: Madhya Pradesh | Q19: Mumbai | R19: 2024-10-14 | S19: Delivered | T19: No | W19: Not Applicable | Y19: =B19 - WEEKDAY(B19,2) + 1 -> 2024-09-30 | Z19: =IF(R19<>"", R19-B19, "") -> 10 | AA19: =IF(L19=0, "No Discount", IF(L19<=20, "Low (1-20%)", "High (20%+)")) -> No Discount
A20: UT-100019 | B20: 2024-10-04 | C20: CUST_10018 | D20: Returning | E20: BOT-JGR-M | F20: Bottoms | G20: Joggers | H20: 1499 | I20: 2 | J20: 2998 | L20: 0 | M20: Wallet | N20: Instagram Shop | O20: Surat | P20: Gujarat | Q20: Mumbai | R20: 2024-10-13 | S20: Delivered | T20: Yes | U20: Size Issue | V20: 2024-10-30 | W20: Processed | Y20: =B20 - WEEKDAY(B20,2) + 1 -> 2024-09-30 | Z20: =IF(R20<>"", R20-B20, "") -> 9 | AA20: =IF(L20=0, "No Discount", IF(L20<=20, "Low (1-20%)", "High (20%+)")) -> No Discount
A21: UT-100020 | B21: 2024-10-05 | C21: CUST_10019 | D21: New | E21: OUT-VST-S | F21: Outerwear | G21: Puffer Vest | H21: 3999 | I21: 1 | J21: 3999 | K21: DIWALI20 | L21: 20 | M21: COD | N21: Website | O21: Patna | P21: Bihar | Q21: Delhi | S21: RTO | T21: No | W21: Not Applicable | Y21: =B21 - WEEKDAY(B21,2) + 1 -> 2024-09-30 | Z21: =IF(R21<>"", R21-B21, "") | AA21: =IF(L21=0, "No Discount", IF(L21<=20, "Low (1-20%)", "High (20%+)")) -> Low (1-20%)
A22: UT-100021 | B22: 2024-10-05 | C22: CUST_10020 | D22: New | E22: TOP-TUN-L | F22: Tops | G22: Tunic Top | H22: 1699 | I22: 1 | J22: 1699 | L22: 0 | M22: UPI | N22: Mobile App | O22: Bhopal | P22: Madhya Pradesh | Q22: Mumbai | R22: 2024-10-15 | S22: Delivered | T22: No | W22: Not Applicable | Y22: =B22 - WEEKDAY(B22,2) + 1 -> 2024-09-30 | Z22: =IF(R22<>"", R22-B22, "") -> 10 | AA22: =IF(L22=0, "No Discount", IF(L22<=20, "Low (1-20%)", "High (20%+)")) -> No Discount
A23: UT-100022 | B23: 2024-10-05 | C23: CUST_10021 | D23: Returning | E23: DRS-SHT-XS | F23: Dresses | G23: Shirt Dress | H23: 2399 | I23: 1 | J23: 2399 | L23: 0 | M23: Credit Card | N23: Website | O23: Nagpur | P23: Maharashtra | Q23: Mumbai | R23: 2024-10-16 | S23: Delivered | T23: Yes | U23: Quality Defect | V23: 2024-11-02 | W23: Processed | Y23: =B23 - WEEKDAY(B23,2) + 1 -> 2024-09-30 | Z23: =IF(R23<>"", R23-B23, "") -> 11 | AA23: =IF(L23=0, "No Discount", IF(L23<=20, "Low (1-20%)", "High (20%+)")) -> No Discount
A24: UT-100023 | B24: 2024-10-05 | C24: CUST_10022 | D24: New | E24: ACC-BLT-M | F24: Accessories | G24: Leather Belt | H24: 899 | I24: 1 | J24: 899 | K24: FLAT10 | L24: 10 | M24: Debit Card | N24: Mobile App | O24: Coimbatore | P24: Tamil Nadu | Q24: Bangalore | R24: 2024-10-17 | S24: Delivered | T24: No | W24: Not Applicable | Y24: =B24 - WEEKDAY(B24,2) + 1 -> 2024-09-30 | Z24: =IF(R24<>"", R24-B24, "") -> 12 | AA24: =IF(L24=0, "No Discount", IF(L24<=20, "Low (1-20%)", "High (20%+)")) -> Low (1-20%)
A25: UT-100024 | B25: 2024-10-06 | C25: CUST_10023 | D25: New | E25: BOT-SHT-M | F25: Bottoms | G25: Cotton Shorts | H25: 1199 | I25: 3 | J25: 3597 | L25: 0 | M25: COD | N25: Instagram Shop | O25: Kochi | P25: Kerala | Q25: Bangalore | R25: 2024-10-18 | S25: Delivered | T25: Yes | U25: Changed Mind | V25: 2024-11-05 | W25: Processed | Y25: =B25 - WEEKDAY(B25,2) + 1 -> 2024-09-30 | Z25: =IF(R25<>"", R25-B25, "") -> 12 | AA25: =IF(L25=0, "No Discount", IF(L25<=20, "Low (1-20%)", "High (20%+)")) -> No Discount
A26: UT-100025 | B26: 2024-10-06 | C26: CUST_10024 | D26: New | E26: TOP-PLO-L | F26: Tops | G26: Polo Shirt | H26: 1799 | I26: 2 | J26: 3598 | L26: 0 | M26: UPI | N26: Website | O26: Vizag | P26: Andhra Pradesh | Q26: Bangalore | R26: 2024-10-17 | S26: Delivered | T26: No | W26: Not Applicable | Y26: =B26 - WEEKDAY(B26,2) + 1 -> 2024-09-30 | Z26: =IF(R26<>"", R26-B26, "") -> 11 | AA26: =IF(L26=0, "No Discount", IF(L26<=20, "Low (1-20%)", "High (20%+)")) -> No Discount
A27: UT-100026 | B27: 2024-10-06 | C27: CUST_10025 | D27: New | E27: DRS-WRK-M | F27: Dresses | G27: Work Dress | H27: 2699 | I27: 1 | J27: 2699 | L27: 0 | M27: Credit Card | N27: Mobile App | O27: Thiruvananthapuram | P27: Kerala | Q27: Bangalore | R27: 2024-10-18 | S27: Delivered | T27: No | W27: Not Applicable | Y27: =B27 - WEEKDAY(B27,2) + 1 -> 2024-09-30 | Z27: =IF(R27<>"", R27-B27, "") -> 12 | AA27: =IF(L27=0, "No Discount", IF(L27<=20, "Low (1-20%)", "High (20%+)")) -> No Discount
A28: UT-100027 | B28: 2024-10-06 | C28: CUST_10026 | D28: Returning | E28: OUT-TRN-L | F28: Outerwear | G28: Trench Coat | H28: 4599 | I28: 1 | J28: 4599 | K28: FLAT10 | L28: 10 | M28: Debit Card | N28: Website | O28: Mysore | P28: Karnataka | Q28: Bangalore | R28: 2024-10-19 | S28: Delivered | T28: Yes | U28: Size Issue | V28: 2024-11-08 | W28: Processed | Y28: =B28 - WEEKDAY(B28,2) + 1 -> 2024-09-30 | Z28: =IF(R28<>"", R28-B28, "") -> 13 | AA28: =IF(L28=0, "No Discount", IF(L28<=20, "Low (1-20%)", "High (20%+)")) -> Low (1-20%)
A29: UT-100028 | B29: 2024-10-07 | C29: CUST_10027 | D29: New | E29: ACC-HAT-OS | F29: Accessories | G29: Fedora Hat | H29: 1099 | I29: 1 | J29: 1099 | L29: 0 | M29: UPI | N29: Instagram Shop | O29: Vadodara | P29: Gujarat | Q29: Mumbai | R29: 2024-10-20 | S29: Delivered | T29: No | W29: Not Applicable | Y29: =B29 - WEEKDAY(B29,2) + 1 -> 2024-10-07 | Z29: =IF(R29<>"", R29-B29, "") -> 13 | AA29: =IF(L29=0, "No Discount", IF(L29<=20, "Low (1-20%)", "High (20%+)")) -> No Discount
A30: UT-100029 | B30: 2024-10-07 | C30: CUST_10028 | D30: New | E30: TOP-DNM-M | F30: Tops | G30: Denim Shirt | H30: 1899 | I30: 1 | J30: 1899 | L30: 0 | M30: COD | N30: Mobile App | O30: Rajkot | P30: Gujarat | Q30: Mumbai | S30: RTO | T30: No | W30: Not Applicable | Y30: =B30 - WEEKDAY(B30,2) + 1 -> 2024-10-07 | Z30: =IF(R30<>"", R30-B30, "") | AA30: =IF(L30=0, "No Discount", IF(L30<=20, "Low (1-20%)", "High (20%+)")) -> No Discount
A31: UT-100030 | B31: 2024-10-07 | C31: CUST_10029 | D31: New | E31: BOT-CRG-L | F31: Bottoms | G31: Cargo Pants | H31: 2199 | I31: 1 | J31: 2199 | K31: DIWALI20 | L31: 20 | M31: Credit Card | N31: Website | O31: Kanpur | P31: Uttar Pradesh | Q31: Delhi | R31: 2024-10-20 | S31: Delivered | T31: No | W31: Not Applicable | Y31: =B31 - WEEKDAY(B31,2) + 1 -> 2024-10-07 | Z31: =IF(R31<>"", R31-B31, "") -> 13 | AA31: =IF(L31=0, "No Discount", IF(L31<=20, "Low (1-20%)", "High (20%+)")) -> Low (1-20%)
A32: UT-100031 | B32: 2024-10-07 | C32: CUST_10030 | D32: Returning | E32: DRS-EVE-S | F32: Dresses | G32: Evening Gown | H32: 5499 | I32: 1 | J32: 5499 | L32: 0 | M32: Credit Card | N32: Mobile App | O32: Mumbai | P32: Maharashtra | Q32: Mumbai | R32: 2024-10-21 | S32: Delivered | T32: Yes | U32: Size Issue | V32: 2024-11-10 | W32: Processed | Y32: =B32 - WEEKDAY(B32,2) + 1 -> 2024-10-07 | Z32: =IF(R32<>"", R32-B32, "") -> 14 | AA32: =IF(L32=0, "No Discount", IF(L32<=20, "Low (1-20%)", "High (20%+)")) -> No Discount
A33: UT-100032 | B33: 2024-10-08 | C33: CUST_10031 | D33: New | E33: TOP-BAS-M | F33: Tops | G33: Basic Tank | H33: 899 | I33: 2 | J33: 1798 | L33: 0 | M33: UPI | N33: Website | O33: Delhi | P33: Delhi | Q33: Delhi | R33: 2024-10-14 | S33: Delivered | T33: No | W33: Not Applicable | Y33: =B33 - WEEKDAY(B33,2) + 1 -> 2024-10-07 | Z33: =IF(R33<>"", R33-B33, "") -> 6 | AA33: =IF(L33=0, "No Discount", IF(L33<=20, "Low (1-20%)", "High (20%+)")) -> No Discount
A34: UT-100033 | B34: 2024-10-08 | C34: CUST_10032 | D34: New | E34: OUT-WOL-L | F34: Outerwear | G34: Wool Coat | H34: 6999 | I34: 1 | J34: 6999 | K34: FIRST15 | L34: 15 | M34: Debit Card | N34: Instagram Shop | O34: Kolkata | P34: West Bengal | Q34: Delhi | R34: 2024-10-16 | S34: Delivered | T34: Yes | U34: Quality Defect | V34: 2024-11-05 | W34: Processed | Y34: =B34 - WEEKDAY(B34,2) + 1 -> 2024-10-07 | Z34: =IF(R34<>"", R34-B34, "") -> 8 | AA34: =IF(L34=0, "No Discount", IF(L34<=20, "Low (1-20%)", "High (20%+)")) -> Low (1-20%)
A35: UT-100034 | B35: 2024-10-08 | C35: CUST_10033 | D35: Returning | E35: ACC-WCH-OS | F35: Accessories | G35: Fashion Watch | H35: 2999 | I35: 1 | J35: 2999 | L35: 0 | M35: Credit Card | N35: Mobile App | O35: Chennai | P35: Tamil Nadu | Q35: Bangalore | R35: 2024-10-15 | S35: Delivered | T35: No | W35: Not Applicable | Y35: =B35 - WEEKDAY(B35,2) + 1 -> 2024-10-07 | Z35: =IF(R35<>"", R35-B35, "") -> 7 | AA35: =IF(L35=0, "No Discount", IF(L35<=20, "Low (1-20%)", "High (20%+)")) -> No Discount
A36: UT-100035 | B36: 2024-10-08 | C36: CUST_10034 | D36: New | E36: BOT-DNM-S | F36: Bottoms | G36: Denim Shorts | H36: 1599 | I36: 1 | J36: 1599 | L36: 0 | M36: COD | N36: Website | O36: Hyderabad | P36: Telangana | Q36: Bangalore | R36: 2024-10-17 | S36: Delivered | T36: Yes | U36: Size Issue | V36: 2024-11-08 | W36: Processed | Y36: =B36 - WEEKDAY(B36,2) + 1 -> 2024-10-07 | Z36: =IF(R36<>"", R36-B36, "") -> 9 | AA36: =IF(L36=0, "No Discount", IF(L36<=20, "Low (1-20%)", "High (20%+)")) -> No Discount
A37: UT-100036 | B37: 2024-10-09 | C37: CUST_10035 | D37: New | E37: DRS-SUN-M | F37: Dresses | G37: Sundress | H37: 1999 | I37: 1 | J37: 1999 | K37: DIWALI20 | L37: 20 | M37: Wallet | N37: Mobile App | O37: Pune | P37: Maharashtra | Q37: Mumbai | R37: 2024-10-16 | S37: Delivered | T37: No | W37: Not Applicable | Y37: =B37 - WEEKDAY(B37,2) + 1 -> 2024-10-07 | Z37: =IF(R37<>"", R37-B37, "") -> 7 | AA37: =IF(L37=0, "No Discount", IF(L37<=20, "Low (1-20%)", "High (20%+)")) -> Low (1-20%)
A38: UT-100037 | B38: 2024-10-09 | C38: CUST_10036 | D38: New | E38: TOP-RFL-S | F38: Tops | G38: Ruffle Top | H38: 1799 | I38: 1 | J38: 1799 | L38: 0 | M38: UPI | N38: Instagram Shop | O38: Ahmedabad | P38: Gujarat | Q38: Mumbai | R38: 2024-10-17 | S38: Delivered | T38: Yes | U38: Changed Mind | V38: 2024-11-12 | W38: Processed | Y38: =B38 - WEEKDAY(B38,2) + 1 -> 2024-10-07 | Z38: =IF(R38<>"", R38-B38, "") -> 8 | AA38: =IF(L38=0, "No Discount", IF(L38<=20, "Low (1-20%)", "High (20%+)")) -> No Discount
A39: UT-100038 | B39: 2024-10-09 | C39: CUST_10037 | D39: Returning | E39: OUT-LTH-M | F39: Outerwear | G39: Leather Jacket | H39: 7999 | I39: 1 | J39: 7999 | L39: 0 | M39: Credit Card | N39: Website | O39: Jaipur | P39: Rajasthan | Q39: Delhi | R39: 2024-10-18 | S39: Delivered | T39: No | W39: Not Applicable | Y39: =B39 - WEEKDAY(B39,2) + 1 -> 2024-10-07 | Z39: =IF(R39<>"", R39-B39, "") -> 9 | AA39: =IF(L39=0, "No Discount", IF(L39<=20, "Low (1-20%)", "High (20%+)")) -> No Discount
A40: UT-100039 | B40: 2024-10-09 | C40: CUST_10038 | D40: New | E40: ACC-SNG-OS | F40: Accessories | G40: Sunglasses | H40: 1499 | I40: 1 | J40: 1499 | K40: FLAT10 | L40: 10 | M40: Debit Card | N40: Mobile App | O40: Lucknow | P40: Uttar Pradesh | Q40: Delhi | R40: 2024-10-17 | S40: Delivered | T40: No | W40: Not Applicable | Y40: =B40 - WEEKDAY(B40,2) + 1 -> 2024-10-07 | Z40: =IF(R40<>"", R40-B40, "") -> 8 | AA40: =IF(L40=0, "No Discount", IF(L40<=20, "Low (1-20%)", "High (20%+)")) -> Low (1-20%)
...

Sheet Trend_Analysis
A1: Week Start | B1: Orders | C1: Return Rate | D1: Avg Discount% | E1: Delivered_Orders | F1: Returned Orders
A2: =MIN(Working_Data!Y:Y) -> 2024-09-30 | B2: =COUNTIF(Working_Data!Y:Y, A2) -> 27 | C2: =COUNTIFS(Working_Data!Y:Y, A2, Working_Data!S:S, "*Delivered*") -> 24 | D2: =AVERAGEIF(Working_Data!$Y:$Y, A2, Working_Data!$L:$L) -> 5.1851852 | E2: =COUNTIFS(Working_Data!$Y:$Y, A2, Working_Data!$S:$S, "Delivered") -> 24 | F2: =COUNTIFS(Working_Data!$Y:$Y, A2, Working_Data!$T:$T, "Yes") -> 11
A3: =A2+7 -> 2024-10-07 | B3: =COUNTIF(Working_Data!Y:Y, A3) -> 29 | C3: =COUNTIFS(Working_Data!Y:Y, A2, Working_Data!S:S, "*Delivered*") -> 24 | D3: =AVERAGEIF(Working_Data!$Y:$Y, A3, Working_Data!$L:$L) -> 5.1724138 | E3: =COUNTIFS(Working_Data!$Y:$Y, A3, Working_Data!$S:$S, "Delivered") -> 27 | F3: =COUNTIFS(Working_Data!$Y:$Y, A3, Working_Data!$T:$T, "Yes") -> 11
A4: =A3+7 -> 2024-10-14 | B4: =COUNTIF(Working_Data!Y:Y, A4) -> 28 | C4: =COUNTIFS(Working_Data!Y:Y, A3, Working_Data!S:S, "*Delivered*") -> 27 | D4: =AVERAGEIF(Working_Data!$Y:$Y, A4, Working_Data!$L:$L) -> 5.1785714 | E4: =COUNTIFS(Working_Data!$Y:$Y, A4, Working_Data!$S:$S, "Delivered") -> 26 | F4: =COUNTIFS(Working_Data!$Y:$Y, A4, Working_Data!$T:$T, "Yes") -> 13
A5: =A4+7 -> 2024-10-21 | B5: =COUNTIF(Working_Data!Y:Y, A5) -> 27 | C5: =COUNTIFS(Working_Data!Y:Y, A4, Working_Data!S:S, "*Delivered*") -> 26 | D5: =AVERAGEIF(Working_Data!$Y:$Y, A5, Working_Data!$L:$L) -> 5.5555556 | E5: =COUNTIFS(Working_Data!$Y:$Y, A5, Working_Data!$S:$S, "Delivered") -> 24 | F5: =COUNTIFS(Working_Data!$Y:$Y, A5, Working_Data!$T:$T, "Yes") -> 10
A6: =A5+7 -> 2024-10-28 | B6: =COUNTIF(Working_Data!Y:Y, A6) -> 33 | C6: =COUNTIFS(Working_Data!Y:Y, A5, Working_Data!S:S, "*Delivered*") -> 24 | D6: =AVERAGEIF(Working_Data!$Y:$Y, A6, Working_Data!$L:$L) -> 40 | E6: =COUNTIFS(Working_Data!$Y:$Y, A6, Working_Data!$S:$S, "Delivered") -> 31 | F6: =COUNTIFS(Working_Data!$Y:$Y, A6, Working_Data!$T:$T, "Yes") -> 24
A7: =A6+7 -> 2024-11-04 | B7: =COUNTIF(Working_Data!Y:Y, A7) -> 21 | C7: =COUNTIFS(Working_Data!Y:Y, A6, Working_Data!S:S, "*Delivered*") -> 31 | D7: =AVERAGEIF(Working_Data!$Y:$Y, A7, Working_Data!$L:$L) -> 16.190476 | E7: =COUNTIFS(Working_Data!$Y:$Y, A7, Working_Data!$S:$S, "Delivered") -> 20 | F7: =COUNTIFS(Working_Data!$Y:$Y, A7, Working_Data!$T:$T, "Yes") -> 11
A8: =A7+7 -> 2024-11-11 | B8: =COUNTIF(Working_Data!Y:Y, A8) -> 21 | C8: =COUNTIFS(Working_Data!Y:Y, A7, Working_Data!S:S, "*Delivered*") -> 20 | D8: =AVERAGEIF(Working_Data!$Y:$Y, A8, Working_Data!$L:$L) -> 4.2857143 | E8: =COUNTIFS(Working_Data!$Y:$Y, A8, Working_Data!$S:$S, "Delivered") -> 20 | F8: =COUNTIFS(Working_Data!$Y:$Y, A8, Working_Data!$T:$T, "Yes") -> 12
A9: =A8+7 -> 2024-11-18 | B9: =COUNTIF(Working_Data!Y:Y, A9) -> 21 | C9: =COUNTIFS(Working_Data!Y:Y, A8, Working_Data!S:S, "*Delivered*") -> 20 | D9: =AVERAGEIF(Working_Data!$Y:$Y, A9, Working_Data!$L:$L) -> 3.5714286 | E9: =COUNTIFS(Working_Data!$Y:$Y, A9, Working_Data!$S:$S, "Delivered") -> 20 | F9: =COUNTIFS(Working_Data!$Y:$Y, A9, Working_Data!$T:$T, "Yes") -> 11
A10: =A9+7 -> 2024-11-25 | B10: =COUNTIF(Working_Data!Y:Y, A10) -> 22 | C10: =COUNTIFS(Working_Data!Y:Y, A9, Working_Data!S:S, "*Delivered*") -> 20 | D10: =AVERAGEIF(Working_Data!$Y:$Y, A10, Working_Data!$L:$L) -> 5.4545455 | E10: =COUNTIFS(Working_Data!$Y:$Y, A10, Working_Data!$S:$S, "Delivered") -> 21 | F10: =COUNTIFS(Working_Data!$Y:$Y, A10, Working_Data!$T:$T, "Yes") -> 13
A11: =A10+7 -> 2024-12-02 | B11: =COUNTIF(Working_Data!Y:Y, A11) -> 28 | C11: =COUNTIFS(Working_Data!Y:Y, A10, Working_Data!S:S, "*Delivered*") -> 21 | D11: =AVERAGEIF(Working_Data!$Y:$Y, A11, Working_Data!$L:$L) -> 8.5714286 | E11: =COUNTIFS(Working_Data!$Y:$Y, A11, Working_Data!$S:$S, "Delivered") -> 27 | F11: =COUNTIFS(Working_Data!$Y:$Y, A11, Working_Data!$T:$T, "Yes") -> 11
A12: =A11+7 -> 2024-12-09 | B12: =COUNTIF(Working_Data!Y:Y, A12) -> 28 | C12: =COUNTIFS(Working_Data!Y:Y, A11, Working_Data!S:S, "*Delivered*") -> 27 | D12: =AVERAGEIF(Working_Data!$Y:$Y, A12, Working_Data!$L:$L) -> 6.4285714 | E12: =COUNTIFS(Working_Data!$Y:$Y, A12, Working_Data!$S:$S, "Delivered") -> 27 | F12: =COUNTIFS(Working_Data!$Y:$Y, A12, Working_Data!$T:$T, "Yes") -> 16
A13: =A12+7 -> 2024-12-16 | B13: =COUNTIF(Working_Data!Y:Y, A13) -> 28 | C13: =COUNTIFS(Working_Data!Y:Y, A12, Working_Data!S:S, "*Delivered*") -> 27 | D13: =AVERAGEIF(Working_Data!$Y:$Y, A13, Working_Data!$L:$L) -> 7.1428571 | E13: =COUNTIFS(Working_Data!$Y:$Y, A13, Working_Data!$S:$S, "Delivered") -> 28 | F13: =COUNTIFS(Working_Data!$Y:$Y, A13, Working_Data!$T:$T, "Yes") -> 17
A14: =A13+7 -> 2024-12-23 | B14: =COUNTIF(Working_Data!Y:Y, A14) -> 28 | C14: =COUNTIFS(Working_Data!Y:Y, A13, Working_Data!S:S, "*Delivered*") -> 28 | D14: =AVERAGEIF(Working_Data!$Y:$Y, A14, Working_Data!$L:$L) -> 6.4285714 | E14: =COUNTIFS(Working_Data!$Y:$Y, A14, Working_Data!$S:$S, "Delivered") -> 28 | F14: =COUNTIFS(Working_Data!$Y:$Y, A14, Working_Data!$T:$T, "Yes") -> 17
A15: =A14+7 -> 2024-12-30 | B15: =COUNTIF(Working_Data!Y:Y, A15) -> 5 | C15: =COUNTIFS(Working_Data!Y:Y, A14, Working_Data!S:S, "*Delivered*") -> 28 | D15: =AVERAGEIF(Working_Data!$Y:$Y, A15, Working_Data!$L:$L) -> 8 | E15: =COUNTIFS(Working_Data!$Y:$Y, A15, Working_Data!$S:$S, "Delivered") -> 5 | F15: =COUNTIFS(Working_Data!$Y:$Y, A15, Working_Data!$T:$T, "Yes") -> 3
A16: =A15+7 -> 2025-01-06 | B16: =COUNTIF(Working_Data!Y:Y, A16) -> 0 | C16: =COUNTIFS(Working_Data!Y:Y, A15, Working_Data!S:S, "*Delivered*") -> 5 | D16: 0 | E16: =COUNTIFS(Working_Data!$Y:$Y, A16, Working_Data!$S:$S, "Delivered") -> 0 | F16: =COUNTIFS(Working_Data!$Y:$Y, A16, Working_Data!$T:$T, "Yes") -> 0
A21: Discount Category | B21: Total Orders | C21: Returns | D21: Return Rate
A22: No Discount | B22: =COUNTIF(Working_Data!AA:AA, "No Discount") -> 206 | C22: =COUNTIFS(Working_Data!AA:AA, "No Discount", Working_Data!T:T, "Yes") -> 103 | D22: =C22/B22 -> 0.5
A23: Low (1-20%) | B23: =COUNTIF(Working_Data!AA:AA, "Low (1-20%)") -> 100 | C23: =COUNTIFS(Working_Data!AA:AA, "Low (1-20%)", Working_Data!T:T, "Yes") -> 48 | D23: =C23/B23 -> 0.48
A24: High (20%+) | B24: =COUNTIF(Working_Data!AA:AA, "High (20%+)") -> 40 | C24: =COUNTIFS(Working_Data!AA:AA, "High (20%+)", Working_Data!T:T, "Yes") -> 29 | D24: =C24/B24 -> 0.725

Sheet Descriptive_Analysis
A1: Order ID | B1: Qty | C1: Total | D1: Return_Rate | E1: Return | F1: Net_Revenue | G1: AOV | N1: SKU | O1: Total (Rs)
A2: =COUNTA(Working_Data!A2:A347) -> 346 | B2: =SUM(Working_Data!I:I) -> 409 | C2: =SUM(Working_Data!J:J) -> 1023789 | D2: =COUNTIF(Working_Data!T:T, "Yes") / COUNTIF(Working_Data!S:S, "Delivered") -> 0.54878049 | E2: =COUNTIF(Working_Data!U2:U347,"<>") -> 180 | F2: =SUMPRODUCT(Working_Data!J2:J347*(1- VALUE(SUBSTITUTE(Working_Data!L2:L347,"%",""))/100)) -> 909607.35 | G2: =F2/A2 -> 2628.923 | N2: TOP-CAS-M | O2: =SUMIF(Working_Data!E:E, N2, Working_Data!J:J) -> 2598
N3: DRS-FRM-S | O3: =SUMIF(Working_Data!E:E, N3, Working_Data!J:J) -> 2499
E4: Month | F4: Orders | N4: BOT-JNS-L | O4: =SUMIF(Working_Data!E:E, N4, Working_Data!J:J) -> 1899
E5: Oct | F5: =COUNTIFS(Working_Data!B:B,">="&DATE(2024,10,1),Working_Data!B:B,"<="&DATE(2024,10,31)) -> 132 | N5: OUT-JKT-XL | O5: =SUMIF(Working_Data!E:E, N5, Working_Data!J:J) -> 3499
E6: Nov | F6: =COUNTIFS(Working_Data!B:B,">="&DATE(2024,11,1),Working_Data!B:B,"<="&DATE(2024,11,30)) -> 93 | N6: ACC-SCF-OS | O6: =SUMIF(Working_Data!E:E, N6, Working_Data!J:J) -> 2397
E7: Dec | F7: =COUNTIFS(Working_Data!B:B,">="&DATE(2024,12,1),Working_Data!B:B,"<="&DATE(2024,12,31)) -> 121 | N7: TOP-FRM-S | O7: =SUMIF(Working_Data!E:E, N7, Working_Data!J:J) -> 3198
N8: DRS-CAS-M | O8: =SUMIF(Working_Data!E:E, N8, Working_Data!J:J) -> 2199
F9: Reason | G9: Count | N9: BOT-TRS-L | O9: =SUMIF(Working_Data!E:E, N9, Working_Data!J:J) -> 2299
E10: 1 | F10: Size Issue | G10: =COUNTIF(Working_Data!U2:U347, "Size Issue") -> 67 | N10: TOP-CAS-XL | O10: =SUMIF(Working_Data!E:E, N10, Working_Data!J:J) -> 6995
E11: 2 | F11: Quality Defect | G11: =COUNTIF(Working_Data!U2:U347, "Quality Defect") -> 32 | N11: OUT-BLZ-M | O11: =SUMIF(Working_Data!E:E, N11, Working_Data!J:J) -> 4999
E12: 3 | F12: Changed Mind | G12: =COUNTIF(Working_Data!U2:U347, "Changed Mind") -> 29 | N12: ACC-BAG-OS | O12: =SUMIF(Working_Data!E:E, N12, Working_Data!J:J) -> 2598
E13: 4 | F13: Wrong Item | G13: =COUNTIF(Working_Data!U2:U347, "Wrong Item") -> 28 | N13: DRS-PRT-S | O13: =SUMIF(Working_Data!E:E, N13, Working_Data!J:J) -> 3299
E14: 5 | F14: Damaged in Transit | G14: =COUNTIF(Working_Data!U2:U347, "Damaged in Transit") -> 24 | N14: TOP-SLK-M | O14: =SUMIF(Working_Data!E:E, N14, Working_Data!J:J) -> 2499
N15: BOT-SKT-S | O15: =SUMIF(Working_Data!E:E, N15, Working_Data!J:J) -> 3598
N16: OUT-CRD-L | O16: =SUMIF(Working_Data!E:E, N16, Working_Data!J:J) -> 2799
N17: ACC-JWL-OS | O17: =SUMIF(Working_Data!E:E, N17, Working_Data!J:J) -> 2396
E18: Top 5 SKUs | F18: Top 5 SKUs Total | N18: TOP-CRP-XS | O18: =SUMIF(Working_Data!E:E, N18, Working_Data!J:J) -> 999
E19: {=INDEX($N$2:$N$337, SMALL(IF($O$2:$O$337=F19, ROW($O$2:$O$337)-ROW($O$2)+1), COUNTIF($F$19:F19, F19)))} -> OUT-CPE-M | F19: =LARGE($O$2:$O$337, 1) -> 10598 | N19: DRS-MAX-M | O19: =SUMIF(Working_Data!E:E, N19, Working_Data!J:J) -> 2899
E20: {=INDEX($N$2:$N$337, SMALL(IF($O$2:$O$337=F20, ROW($O$2:$O$337)-ROW($O$2)+1), COUNTIF($F$19:F20, F20)))} -> OUT-VLV-L | F20: =LARGE($O$2:$O$337, 2) -> 10498 | N20: BOT-JGR-M | O20: =SUMIF(Working_Data!E:E, N20, Working_Data!J:J) -> 2998
E21: {=INDEX($N$2:$N$337, SMALL(IF($O$2:$O$337=F21, ROW($O$2:$O$337)-ROW($O$2)+1), COUNTIF($F$19:F21, F21)))} -> DRS-EVE-S | F21: =LARGE($O$2:$O$337, 3) -> 10098 | N21: OUT-VST-S | O21: =SUMIF(Working_Data!E:E, N21, Working_Data!J:J) -> 3999
E22: {=INDEX($N$2:$N$337, SMALL(IF($O$2:$O$337=F22, ROW($O$2:$O$337)-ROW($O$2)+1), COUNTIF($F$19:F22, F22)))} -> DRS-LHG-M | F22: =LARGE($O$2:$O$337, 4) -> 8999 | N22: TOP-TUN-L | O22: =SUMIF(Working_Data!E:E, N22, Working_Data!J:J) -> 1699
E23: {=INDEX($N$2:$N$337, SMALL(IF($O$2:$O$337=F23, ROW($O$2:$O$337)-ROW($O$2)+1), COUNTIF($F$19:F23, F23)))} -> OUT-FUR-L | F23: =LARGE($O$2:$O$337, 5) -> 8999 | N23: DRS-SHT-XS | O23: =SUMIF(Working_Data!E:E, N23, Working_Data!J:J) -> 2399
N24: ACC-BLT-M | O24: =SUMIF(Working_Data!E:E, N24, Working_Data!J:J) -> 899
N25: BOT-SHT-M | O25: =SUMIF(Working_Data!E:E, N25, Working_Data!J:J) -> 3597
N26: TOP-PLO-L | O26: =SUMIF(Working_Data!E:E, N26, Working_Data!J:J) -> 3598
N27: DRS-WRK-M | O27: =SUMIF(Working_Data!E:E, N27, Working_Data!J:J) -> 2699
N28: OUT-TRN-L | O28: =SUMIF(Working_Data!E:E, N28, Working_Data!J:J) -> 4599
N29: ACC-HAT-OS | O29: =SUMIF(Working_Data!E:E, N29, Working_Data!J:J) -> 1099
N30: TOP-DNM-M | O30: =SUMIF(Working_Data!E:E, N30, Working_Data!J:J) -> 1899
N31: BOT-CRG-L | O31: =SUMIF(Working_Data!E:E, N31, Working_Data!J:J) -> 2199
N32: DRS-EVE-S | O32: =SUMIF(Working_Data!E:E, N32, Working_Data!J:J) -> 10098
N33: TOP-BAS-M | O33: =SUMIF(Working_Data!E:E, N33, Working_Data!J:J) -> 1798
N34: OUT-WOL-L | O34: =SUMIF(Working_Data!E:E, N34, Working_Data!J:J) -> 6999
N35: ACC-WCH-OS | O35: =SUMIF(Working_Data!E:E, N35, Working_Data!J:J) -> 2999
... N337: DRS-CNT-S | O337: =SUMIF(Working_Data!E:E, N337, Working_Data!J:J) -> 4499

Sheet VALIDATION_SUMMARY
A1: Check Name | B1: Formula Used | C1: Result | D1: Pass/Fail
A2: Order ID missing | B2: COUNTBLANK(Working_Data!A2:A347) | C2: =COUNTBLANK(Working_Data!A2:A347) -> 0 | D2: =IF(C2=0, "Pass", "Fail") -> Pass
A3: Duplicate order_id | B3: COUNTIF(Working_Data!A:A, Working_Data!A2)-1 | C3: =COUNTIF(Working_Data!A:A, Working_Data!A2)-1 -> 0 | D3: =IF(C3=0, "Pass", "Fail") -> Pass
A4: Delivered without delivery_date | B4: COUNTIFS( Working_Data!P:P,"Delivered", Working_Data!O:O,"" ) | C4: =COUNTIFS( Working_Data!P:P,"Delivered", Working_Data!O:O,"" ) -> 0 | D4: =IF(C4=0, "Pass", "Fail") -> Pass
A5: Return Yes without reason | B5: COUNTIFS( Working_Data!Q:Q,"Yes", Working_Data!R:R,"" ) | C5: =COUNTIFS( Working_Data!Q:Q,"Yes", Working_Data!R:R,"" ) -> 0 | D5: Pass
A6: Return before delivery | B6: COUNTIFS( Working_Data!S:S,"<"&Working_Data!O:O ) | C6: =SUMPRODUCT(--(Working_Data!V2:V347 < Working_Data!R2:R347) * (Working_Data!V2:V347 <> "")) -> 0 | D6: =IF(C5=0, "Pass", "Fail") -> Pass

Sheet Final_KPIs
A1: Total Orders | B1: Delivered Orders | C1: GMV | D1: Net Revenue | E1: Average Order Value (AOV) | F1: Average Discount %
A2: =COUNTA(Working_Data!A2:A347) -> 346 | B2: =COUNTIF(Working_Data!S:S, "Delivered") -> 328 | C2: =SUM(Working_Data!J:J) -> 1023789 | D2: =SUMPRODUCT(Working_Data!J2:J347, 1-(Working_Data!L2:L347/100)) -> 909607.35 | E2: =AVERAGE(Working_Data!J2:J347) -> 2958.9277 | F2: =AVERAGE(Working_Data!L2:L347) -> 9.7398844

Sheet Cleaning_Log
A1: Issue Type | B1: Column Name | C1: What I Observed | D1: Why It’s a Problem | E1: Action Taken
A2: Missing Value Check | B2: Order ID, Order Date, Customer ID, Unit Price, Qty, Total | C2: No missing values found in critical columns | D2: Critical fields must be present to ensure accurate order, revenue, and fulfillment analysis | E2: No action required
A3: Date logic checks performed (1 violations found) | B3: Order Date, Del Date, Ret Rec | C3: No cases where Del Date occurs before Order Date or Ret Rec occurs before Del Date. B4 is 10/1 while others are 1/10 | D3: Incorrect date order breaks delivery time calculations, return window validation, and leads to inaccurate operational KPIs. | E3: No action required
A4: Corrected mistaken spelling | B4: Status | C4: Delivered was miswritten as delievered | D4: Incorrect spelling leads to miscalculations. | E4: Action taken
A5: Feature Engineering | B5: Added columns weekstart,DeliverDays and DiscountTrap | C5: Raw data was transactional only (row-level) | D5: We could not analyze weekly trends or identify the "Discount Trap" impact without aggregating metrics. | E5: Engineered calculated columns to group sales by week and flag high-risk discount orders.

Sheet Insights_Summary
A1: Key_Insights
A3: Key insights
A4: Weekly orders peak during the Diwali week (28-10-2024), coinciding with the highest discount levels.
A5: Deep discounting during Diwali was counter-productive. While order volume peaked at 33 units, the 73% return rate meant Net Sales actually dropped by ~50% compared to the previous week. We effectively paid to ship inventory back and forth.
A8: Business conclusions
A9: Festive discounts effectively drive short-term demand but increase return-related operational costs.
A10: Promotional effects extend beyond the sale week due to the 30-day return window.
A11: Discount intensity should be optimized to balance GMV growth and net revenue quality.
A14: Business recommendations
A15: Introduce discount caps during peak festive periods to control return rates.
A16: Focus deeper promotions on lower-risk customers rather than blanket discounting.
A17: Improve size guidance and post-purchase communication during high-volume weeks to reduce preventable returns.
... A23: Return rate is calculated using delivered orders only.
